2025-10-16 11:19:58.751 | INFO     | app.core.logging_config:setup_logging:60 - Configuração de logging concluída e interceptadores ativados.
2025-10-16 11:20:03.641 | ERROR    | app.core.exception_handler:global_exception_handler:12 - Erro inesperado na requisição: POST http://127.0.0.1:8000/api/v1/stores/
2025-10-16 11:20:03.641 | ERROR    | app.core.exception_handler:global_exception_handler:13 - Exceção: (sqlalchemy.dialects.postgresql.asyncpg.IntegrityError) <class 'asyncpg.exceptions.NotNullViolationError'>: o valor nulo na coluna "store_id" da relação "stores" viola a restrição de não-nulo
DETAIL:  Registro que falhou contém (null, 1, Vitor Hugo Lemes, , t, 2025-10-16 11:20:03.61488, 2025-10-16 11:20:03.61488).
[SQL: INSERT INTO stores (store_id, name, address, is_active, created_at, updated_at) VALUES ($1::INTEGER, $2::VARCHAR, $3::VARCHAR, $4::BOOLEAN, now(), now()) RETURNING stores.id, stores.created_at, stores.updated_at]
[parameters: (None, 'Vitor Hugo Lemes', '', True)]
(Background on this error at: https://sqlalche.me/e/20/gkpj)
2025-10-16 11:20:03.660 | ERROR    | app.core.exception_handler:global_exception_handler:14 - Traceback: Traceback (most recent call last):
  File "C:\Users\Vitor Lemes\AppData\Local\Programs\Python\Python311\Lib\site-packages\sqlalchemy\dialects\postgresql\asyncpg.py", line 538, in _prepare_and_execute
    self._rows = await prepared_stmt.fetch(*parameters)
                 ^^^^^^^^^^^^^^^^^^^^^^^^^^^^^^^^^^^^^^
  File "C:\Users\Vitor Lemes\AppData\Local\Programs\Python\Python311\Lib\site-packages\asyncpg\prepared_stmt.py", line 176, in fetch
    data = await self.__bind_execute(args, 0, timeout)
           ^^^^^^^^^^^^^^^^^^^^^^^^^^^^^^^^^^^^^^^^^^^
  File "C:\Users\Vitor Lemes\AppData\Local\Programs\Python\Python311\Lib\site-packages\asyncpg\prepared_stmt.py", line 241, in __bind_execute
    data, status, _ = await self.__do_execute(
                      ^^^^^^^^^^^^^^^^^^^^^^^^
  File "C:\Users\Vitor Lemes\AppData\Local\Programs\Python\Python311\Lib\site-packages\asyncpg\prepared_stmt.py", line 230, in __do_execute
    return await executor(protocol)
           ^^^^^^^^^^^^^^^^^^^^^^^^
  File "asyncpg\protocol\protocol.pyx", line 207, in bind_execute
asyncpg.exceptions.NotNullViolationError: o valor nulo na coluna "store_id" da relação "stores" viola a restrição de não-nulo
DETAIL:  Registro que falhou contém (null, 1, Vitor Hugo Lemes, , t, 2025-10-16 11:20:03.61488, 2025-10-16 11:20:03.61488).

The above exception was the direct cause of the following exception:

Traceback (most recent call last):
  File "C:\Users\Vitor Lemes\AppData\Local\Programs\Python\Python311\Lib\site-packages\sqlalchemy\engine\base.py", line 1967, in _exec_single_context
    self.dialect.do_execute(
  File "C:\Users\Vitor Lemes\AppData\Local\Programs\Python\Python311\Lib\site-packages\sqlalchemy\engine\default.py", line 924, in do_execute
    cursor.execute(statement, parameters)
  File "C:\Users\Vitor Lemes\AppData\Local\Programs\Python\Python311\Lib\site-packages\sqlalchemy\dialects\postgresql\asyncpg.py", line 572, in execute
    self._adapt_connection.await_(
  File "C:\Users\Vitor Lemes\AppData\Local\Programs\Python\Python311\Lib\site-packages\sqlalchemy\util\_concurrency_py3k.py", line 131, in await_only
    return current.driver.switch(awaitable)  # type: ignore[no-any-return]
           ^^^^^^^^^^^^^^^^^^^^^^^^^^^^^^^^
  File "C:\Users\Vitor Lemes\AppData\Local\Programs\Python\Python311\Lib\site-packages\sqlalchemy\util\_concurrency_py3k.py", line 196, in greenlet_spawn
    value = await result
            ^^^^^^^^^^^^
  File "C:\Users\Vitor Lemes\AppData\Local\Programs\Python\Python311\Lib\site-packages\sqlalchemy\dialects\postgresql\asyncpg.py", line 550, in _prepare_and_execute
    self._handle_exception(error)
  File "C:\Users\Vitor Lemes\AppData\Local\Programs\Python\Python311\Lib\site-packages\sqlalchemy\dialects\postgresql\asyncpg.py", line 501, in _handle_exception
    self._adapt_connection._handle_exception(error)
  File "C:\Users\Vitor Lemes\AppData\Local\Programs\Python\Python311\Lib\site-packages\sqlalchemy\dialects\postgresql\asyncpg.py", line 789, in _handle_exception
    raise translated_error from error
sqlalchemy.dialects.postgresql.asyncpg.AsyncAdapt_asyncpg_dbapi.IntegrityError: <class 'asyncpg.exceptions.NotNullViolationError'>: o valor nulo na coluna "store_id" da relação "stores" viola a restrição de não-nulo
DETAIL:  Registro que falhou contém (null, 1, Vitor Hugo Lemes, , t, 2025-10-16 11:20:03.61488, 2025-10-16 11:20:03.61488).

The above exception was the direct cause of the following exception:

Traceback (most recent call last):
  File "C:\Users\Vitor Lemes\AppData\Local\Programs\Python\Python311\Lib\site-packages\starlette\middleware\errors.py", line 164, in __call__
    await self.app(scope, receive, _send)
  File "C:\Users\Vitor Lemes\AppData\Local\Programs\Python\Python311\Lib\site-packages\starlette\middleware\cors.py", line 93, in __call__
    await self.simple_response(scope, receive, send, request_headers=headers)
  File "C:\Users\Vitor Lemes\AppData\Local\Programs\Python\Python311\Lib\site-packages\starlette\middleware\cors.py", line 148, in simple_response
    await self.app(scope, receive, send)
  File "C:\Users\Vitor Lemes\AppData\Local\Programs\Python\Python311\Lib\site-packages\starlette\middleware\base.py", line 189, in __call__
    with collapse_excgroups():
  File "C:\Users\Vitor Lemes\AppData\Local\Programs\Python\Python311\Lib\contextlib.py", line 155, in __exit__
    self.gen.throw(typ, value, traceback)
  File "C:\Users\Vitor Lemes\AppData\Local\Programs\Python\Python311\Lib\site-packages\starlette\_utils.py", line 93, in collapse_excgroups
    raise exc
  File "C:\Users\Vitor Lemes\AppData\Local\Programs\Python\Python311\Lib\site-packages\starlette\middleware\base.py", line 191, in __call__
    response = await self.dispatch_func(request, call_next)
               ^^^^^^^^^^^^^^^^^^^^^^^^^^^^^^^^^^^^^^^^^^^^
  File "C:\Users\Vitor Lemes\Downloads\VRSales\api\main.py", line 41, in log_requests
    response = await call_next(request)
               ^^^^^^^^^^^^^^^^^^^^^^^^
  File "C:\Users\Vitor Lemes\AppData\Local\Programs\Python\Python311\Lib\site-packages\starlette\middleware\base.py", line 165, in call_next
    raise app_exc
  File "C:\Users\Vitor Lemes\AppData\Local\Programs\Python\Python311\Lib\site-packages\starlette\middleware\base.py", line 151, in coro
    await self.app(scope, receive_or_disconnect, send_no_error)
  File "C:\Users\Vitor Lemes\AppData\Local\Programs\Python\Python311\Lib\site-packages\starlette\middleware\exceptions.py", line 65, in __call__
    await wrap_app_handling_exceptions(self.app, conn)(scope, receive, send)
  File "C:\Users\Vitor Lemes\AppData\Local\Programs\Python\Python311\Lib\site-packages\starlette\_exception_handler.py", line 64, in wrapped_app
    raise exc
  File "C:\Users\Vitor Lemes\AppData\Local\Programs\Python\Python311\Lib\site-packages\starlette\_exception_handler.py", line 53, in wrapped_app
    await app(scope, receive, sender)
  File "C:\Users\Vitor Lemes\AppData\Local\Programs\Python\Python311\Lib\site-packages\starlette\routing.py", line 756, in __call__
    await self.middleware_stack(scope, receive, send)
  File "C:\Users\Vitor Lemes\AppData\Local\Programs\Python\Python311\Lib\site-packages\starlette\routing.py", line 776, in app
    await route.handle(scope, receive, send)
  File "C:\Users\Vitor Lemes\AppData\Local\Programs\Python\Python311\Lib\site-packages\starlette\routing.py", line 297, in handle
    await self.app(scope, receive, send)
  File "C:\Users\Vitor Lemes\AppData\Local\Programs\Python\Python311\Lib\site-packages\starlette\routing.py", line 77, in app
    await wrap_app_handling_exceptions(app, request)(scope, receive, send)
  File "C:\Users\Vitor Lemes\AppData\Local\Programs\Python\Python311\Lib\site-packages\starlette\_exception_handler.py", line 64, in wrapped_app
    raise exc
  File "C:\Users\Vitor Lemes\AppData\Local\Programs\Python\Python311\Lib\site-packages\starlette\_exception_handler.py", line 53, in wrapped_app
    await app(scope, receive, sender)
  File "C:\Users\Vitor Lemes\AppData\Local\Programs\Python\Python311\Lib\site-packages\starlette\routing.py", line 72, in app
    response = await func(request)
               ^^^^^^^^^^^^^^^^^^^
  File "C:\Users\Vitor Lemes\AppData\Local\Programs\Python\Python311\Lib\contextlib.py", line 222, in __aexit__
    await self.gen.athrow(typ, value, traceback)
  File "C:\Users\Vitor Lemes\Downloads\VRSales\api\app\api\dependencies.py", line 19, in get_db
    yield db
  File "C:\Users\Vitor Lemes\AppData\Local\Programs\Python\Python311\Lib\site-packages\fastapi\routing.py", line 278, in app
    raw_response = await run_endpoint_function(
                   ^^^^^^^^^^^^^^^^^^^^^^^^^^^^
  File "C:\Users\Vitor Lemes\AppData\Local\Programs\Python\Python311\Lib\site-packages\fastapi\routing.py", line 191, in run_endpoint_function
    return await dependant.call(**values)
           ^^^^^^^^^^^^^^^^^^^^^^^^^^^^^^
  File "C:\Users\Vitor Lemes\Downloads\VRSales\api\app\api\endpoints\stores.py", line 36, in create_store
    return await crud.store.create(db=db, obj_in=store_in, current_user=current_user)
           ^^^^^^^^^^^^^^^^^^^^^^^^^^^^^^^^^^^^^^^^^^^^^^^^^^^^^^^^^^^^^^^^^^^^^^^^^^
  File "C:\Users\Vitor Lemes\Downloads\VRSales\api\app\crud\base.py", line 60, in create
    await db.commit()
  File "C:\Users\Vitor Lemes\AppData\Local\Programs\Python\Python311\Lib\site-packages\sqlalchemy\ext\asyncio\session.py", line 1009, in commit
    await greenlet_spawn(self.sync_session.commit)
  File "C:\Users\Vitor Lemes\AppData\Local\Programs\Python\Python311\Lib\site-packages\sqlalchemy\util\_concurrency_py3k.py", line 203, in greenlet_spawn
    result = context.switch(value)
             ^^^^^^^^^^^^^^^^^^^^^
  File "C:\Users\Vitor Lemes\AppData\Local\Programs\Python\Python311\Lib\site-packages\sqlalchemy\orm\session.py", line 2017, in commit
    trans.commit(_to_root=True)
  File "<string>", line 2, in commit
  File "C:\Users\Vitor Lemes\AppData\Local\Programs\Python\Python311\Lib\site-packages\sqlalchemy\orm\state_changes.py", line 139, in _go
    ret_value = fn(self, *arg, **kw)
                ^^^^^^^^^^^^^^^^^^^^
  File "C:\Users\Vitor Lemes\AppData\Local\Programs\Python\Python311\Lib\site-packages\sqlalchemy\orm\session.py", line 1302, in commit
    self._prepare_impl()
  File "<string>", line 2, in _prepare_impl
  File "C:\Users\Vitor Lemes\AppData\Local\Programs\Python\Python311\Lib\site-packages\sqlalchemy\orm\state_changes.py", line 139, in _go
    ret_value = fn(self, *arg, **kw)
                ^^^^^^^^^^^^^^^^^^^^
  File "C:\Users\Vitor Lemes\AppData\Local\Programs\Python\Python311\Lib\site-packages\sqlalchemy\orm\session.py", line 1277, in _prepare_impl
    self.session.flush()
  File "C:\Users\Vitor Lemes\AppData\Local\Programs\Python\Python311\Lib\site-packages\sqlalchemy\orm\session.py", line 4341, in flush
    self._flush(objects)
  File "C:\Users\Vitor Lemes\AppData\Local\Programs\Python\Python311\Lib\site-packages\sqlalchemy\orm\session.py", line 4476, in _flush
    with util.safe_reraise():
  File "C:\Users\Vitor Lemes\AppData\Local\Programs\Python\Python311\Lib\site-packages\sqlalchemy\util\langhelpers.py", line 146, in __exit__
    raise exc_value.with_traceback(exc_tb)
  File "C:\Users\Vitor Lemes\AppData\Local\Programs\Python\Python311\Lib\site-packages\sqlalchemy\orm\session.py", line 4437, in _flush
    flush_context.execute()
  File "C:\Users\Vitor Lemes\AppData\Local\Programs\Python\Python311\Lib\site-packages\sqlalchemy\orm\unitofwork.py", line 466, in execute
    rec.execute(self)
  File "C:\Users\Vitor Lemes\AppData\Local\Programs\Python\Python311\Lib\site-packages\sqlalchemy\orm\unitofwork.py", line 642, in execute
    util.preloaded.orm_persistence.save_obj(
  File "C:\Users\Vitor Lemes\AppData\Local\Programs\Python\Python311\Lib\site-packages\sqlalchemy\orm\persistence.py", line 93, in save_obj
    _emit_insert_statements(
  File "C:\Users\Vitor Lemes\AppData\Local\Programs\Python\Python311\Lib\site-packages\sqlalchemy\orm\persistence.py", line 1233, in _emit_insert_statements
    result = connection.execute(
             ^^^^^^^^^^^^^^^^^^^
  File "C:\Users\Vitor Lemes\AppData\Local\Programs\Python\Python311\Lib\site-packages\sqlalchemy\engine\base.py", line 1418, in execute
    return meth(
           ^^^^^
  File "C:\Users\Vitor Lemes\AppData\Local\Programs\Python\Python311\Lib\site-packages\sqlalchemy\sql\elements.py", line 515, in _execute_on_connection
    return connection._execute_clauseelement(
           ^^^^^^^^^^^^^^^^^^^^^^^^^^^^^^^^^^
  File "C:\Users\Vitor Lemes\AppData\Local\Programs\Python\Python311\Lib\site-packages\sqlalchemy\engine\base.py", line 1640, in _execute_clauseelement
    ret = self._execute_context(
          ^^^^^^^^^^^^^^^^^^^^^^
  File "C:\Users\Vitor Lemes\AppData\Local\Programs\Python\Python311\Lib\site-packages\sqlalchemy\engine\base.py", line 1846, in _execute_context
    return self._exec_single_context(
           ^^^^^^^^^^^^^^^^^^^^^^^^^^
  File "C:\Users\Vitor Lemes\AppData\Local\Programs\Python\Python311\Lib\site-packages\sqlalchemy\engine\base.py", line 1986, in _exec_single_context
    self._handle_dbapi_exception(
  File "C:\Users\Vitor Lemes\AppData\Local\Programs\Python\Python311\Lib\site-packages\sqlalchemy\engine\base.py", line 2353, in _handle_dbapi_exception
    raise sqlalchemy_exception.with_traceback(exc_info[2]) from e
  File "C:\Users\Vitor Lemes\AppData\Local\Programs\Python\Python311\Lib\site-packages\sqlalchemy\engine\base.py", line 1967, in _exec_single_context
    self.dialect.do_execute(
  File "C:\Users\Vitor Lemes\AppData\Local\Programs\Python\Python311\Lib\site-packages\sqlalchemy\engine\default.py", line 924, in do_execute
    cursor.execute(statement, parameters)
  File "C:\Users\Vitor Lemes\AppData\Local\Programs\Python\Python311\Lib\site-packages\sqlalchemy\dialects\postgresql\asyncpg.py", line 572, in execute
    self._adapt_connection.await_(
  File "C:\Users\Vitor Lemes\AppData\Local\Programs\Python\Python311\Lib\site-packages\sqlalchemy\util\_concurrency_py3k.py", line 131, in await_only
    return current.driver.switch(awaitable)  # type: ignore[no-any-return]
           ^^^^^^^^^^^^^^^^^^^^^^^^^^^^^^^^
  File "C:\Users\Vitor Lemes\AppData\Local\Programs\Python\Python311\Lib\site-packages\sqlalchemy\util\_concurrency_py3k.py", line 196, in greenlet_spawn
    value = await result
            ^^^^^^^^^^^^
  File "C:\Users\Vitor Lemes\AppData\Local\Programs\Python\Python311\Lib\site-packages\sqlalchemy\dialects\postgresql\asyncpg.py", line 550, in _prepare_and_execute
    self._handle_exception(error)
  File "C:\Users\Vitor Lemes\AppData\Local\Programs\Python\Python311\Lib\site-packages\sqlalchemy\dialects\postgresql\asyncpg.py", line 501, in _handle_exception
    self._adapt_connection._handle_exception(error)
  File "C:\Users\Vitor Lemes\AppData\Local\Programs\Python\Python311\Lib\site-packages\sqlalchemy\dialects\postgresql\asyncpg.py", line 789, in _handle_exception
    raise translated_error from error
sqlalchemy.exc.IntegrityError: (sqlalchemy.dialects.postgresql.asyncpg.IntegrityError) <class 'asyncpg.exceptions.NotNullViolationError'>: o valor nulo na coluna "store_id" da relação "stores" viola a restrição de não-nulo
DETAIL:  Registro que falhou contém (null, 1, Vitor Hugo Lemes, , t, 2025-10-16 11:20:03.61488, 2025-10-16 11:20:03.61488).
[SQL: INSERT INTO stores (store_id, name, address, is_active, created_at, updated_at) VALUES ($1::INTEGER, $2::VARCHAR, $3::VARCHAR, $4::BOOLEAN, now(), now()) RETURNING stores.id, stores.created_at, stores.updated_at]
[parameters: (None, 'Vitor Hugo Lemes', '', True)]
(Background on this error at: https://sqlalche.me/e/20/gkpj)

