2025-10-17 09:36:57.748 | INFO     | app.core.logging_config:setup_logging:60 - Configuração de logging concluída e interceptadores ativados.
2025-10-17 09:36:57.847 | INFO     | main:log_requests:47 - Request: GET /api/v1/users/me | Status: 401 | Duration: 51.60ms
2025-10-17 09:36:57.847 | INFO     | main:log_requests:47 - Request: GET /api/v1/users/me | Status: 401 | Duration: 0.00ms
2025-10-17 09:37:31.095 | DEBUG    | logging:callHandlers:1706 - Calling on_field_start with no data
2025-10-17 09:37:31.095 | DEBUG    | logging:callHandlers:1706 - Calling on_field_name with data[0:8]
2025-10-17 09:37:31.095 | DEBUG    | logging:callHandlers:1706 - Calling on_field_data with data[9:28]
2025-10-17 09:37:31.111 | DEBUG    | logging:callHandlers:1706 - Calling on_field_end with no data
2025-10-17 09:37:31.111 | DEBUG    | logging:callHandlers:1706 - Calling on_field_start with no data
2025-10-17 09:37:31.111 | DEBUG    | logging:callHandlers:1706 - Calling on_field_name with data[29:37]
2025-10-17 09:37:31.111 | DEBUG    | logging:callHandlers:1706 - Calling on_field_data with data[38:46]
2025-10-17 09:37:31.111 | DEBUG    | logging:callHandlers:1706 - Calling on_field_end with no data
2025-10-17 09:37:31.111 | DEBUG    | logging:callHandlers:1706 - Calling on_end with no data
2025-10-17 09:37:31.445 | DEBUG    | logging:callHandlers:1706 - detected 'bcrypt' backend, version '3.2.0'
2025-10-17 09:37:31.445 | DEBUG    | logging:callHandlers:1706 - 'bcrypt' backend lacks $2$ support, enabling workaround
2025-10-17 09:37:31.695 | INFO     | main:log_requests:47 - Request: POST /api/v1/login/access-token | Status: 200 | Duration: 600.61ms
2025-10-17 09:37:31.712 | INFO     | main:log_requests:47 - Request: GET /api/v1/users/me | Status: 200 | Duration: 8.42ms
2025-10-17 09:49:32.301 | INFO     | main:log_requests:47 - Request: GET /api/v1/users/me | Status: 200 | Duration: 0.00ms
2025-10-17 09:49:32.313 | INFO     | main:log_requests:47 - Request: GET /api/v1/users/me | Status: 200 | Duration: 12.18ms
2025-10-17 09:50:52.195 | INFO     | main:log_requests:47 - Request: GET /api/v1/users/me | Status: 200 | Duration: 0.00ms
2025-10-17 09:50:52.211 | INFO     | main:log_requests:47 - Request: GET /api/v1/users/me | Status: 200 | Duration: 15.44ms
2025-10-17 09:50:55.568 | INFO     | main:log_requests:47 - Request: GET /api/v1/users/me | Status: 200 | Duration: 3.00ms
2025-10-17 09:50:55.569 | INFO     | main:log_requests:47 - Request: GET /api/v1/users/me | Status: 200 | Duration: 0.00ms
2025-10-17 09:50:56.969 | INFO     | main:log_requests:47 - Request: GET /api/v1/users/me | Status: 200 | Duration: 6.14ms
2025-10-17 09:50:56.974 | INFO     | main:log_requests:47 - Request: GET /api/v1/users/me | Status: 200 | Duration: 3.35ms
2025-10-17 09:50:57.672 | INFO     | main:log_requests:47 - Request: GET /api/v1/users/me | Status: 200 | Duration: 1.05ms
2025-10-17 09:50:57.672 | INFO     | main:log_requests:47 - Request: GET /api/v1/users/me | Status: 200 | Duration: 0.00ms
2025-10-17 09:50:58.735 | INFO     | main:log_requests:47 - Request: GET /api/v1/users/me | Status: 200 | Duration: 5.15ms
2025-10-17 09:50:58.742 | INFO     | main:log_requests:47 - Request: GET /api/v1/users/me | Status: 200 | Duration: 4.00ms
2025-10-17 09:55:08.317 | INFO     | main:log_requests:47 - Request: GET /api/v1/users/me | Status: 200 | Duration: 2.68ms
2025-10-17 09:55:08.322 | INFO     | main:log_requests:47 - Request: GET /api/v1/users/me | Status: 200 | Duration: 2.01ms
2025-10-17 10:05:00.973 | INFO     | main:log_requests:47 - Request: GET /api/v1/users/me | Status: 200 | Duration: 2.01ms
2025-10-17 10:05:00.977 | INFO     | main:log_requests:47 - Request: GET /api/v1/users/me | Status: 200 | Duration: 2.64ms
2025-10-17 10:22:47.456 | INFO     | main:log_requests:47 - Request: GET /api/v1/customers/ | Status: 401 | Duration: 0.00ms
2025-10-17 10:22:47.456 | INFO     | main:log_requests:47 - Request: GET /api/v1/customers/ | Status: 401 | Duration: 0.00ms
2025-10-17 10:22:52.169 | DEBUG    | logging:callHandlers:1706 - Calling on_field_start with no data
2025-10-17 10:22:52.169 | DEBUG    | logging:callHandlers:1706 - Calling on_field_name with data[0:8]
2025-10-17 10:22:52.169 | DEBUG    | logging:callHandlers:1706 - Calling on_field_data with data[9:28]
2025-10-17 10:22:52.169 | DEBUG    | logging:callHandlers:1706 - Calling on_field_end with no data
2025-10-17 10:22:52.169 | DEBUG    | logging:callHandlers:1706 - Calling on_field_start with no data
2025-10-17 10:22:52.169 | DEBUG    | logging:callHandlers:1706 - Calling on_field_name with data[29:37]
2025-10-17 10:22:52.169 | DEBUG    | logging:callHandlers:1706 - Calling on_field_data with data[38:46]
2025-10-17 10:22:52.169 | DEBUG    | logging:callHandlers:1706 - Calling on_field_end with no data
2025-10-17 10:22:52.169 | DEBUG    | logging:callHandlers:1706 - Calling on_end with no data
2025-10-17 10:22:52.361 | INFO     | main:log_requests:47 - Request: POST /api/v1/login/access-token | Status: 200 | Duration: 192.87ms
2025-10-17 10:22:52.361 | INFO     | main:log_requests:47 - Request: GET /api/v1/users/me | Status: 200 | Duration: 0.00ms
2025-10-17 10:22:54.096 | INFO     | main:log_requests:47 - Request: GET /api/v1/customers/ | Status: 200 | Duration: 31.80ms
2025-10-17 10:22:54.103 | INFO     | main:log_requests:47 - Request: GET /api/v1/customers/ | Status: 200 | Duration: 0.00ms
2025-10-17 10:22:58.433 | ERROR    | app.core.exception_handler:global_exception_handler:12 - Erro inesperado na requisição: POST http://localhost:8000/api/v1/customers/
2025-10-17 10:22:58.433 | ERROR    | app.core.exception_handler:global_exception_handler:13 - Exceção: (sqlalchemy.dialects.postgresql.asyncpg.IntegrityError) <class 'asyncpg.exceptions.NotNullViolationError'>: o valor nulo na coluna "store_id" da relação "customers" viola a restrição de não-nulo
DETAIL:  Registro que falhou contém (2, Raphael, 16996440178, raphaeldestefanobraga@gmail.com, null, null, null, 0, 0, 2025-10-17 10:22:58.422392, 2025-10-17 10:22:58.422392).
[SQL: INSERT INTO customers (full_name, phone_number, email, document_number, store_id, last_seen, total_spent, loyalty_points, created_at, updated_at) VALUES ($1::VARCHAR, $2::VARCHAR, $3::VARCHAR, $4::VARCHAR, $5::INTEGER, $6::TIMESTAMP WITHOUT TIME ZONE, $7::FLOAT, $8::INTEGER, now(), now()) RETURNING customers.id, customers.created_at, customers.updated_at]
[parameters: ('Raphael', '16996440178', 'raphaeldestefanobraga@gmail.com', None, None, None, 0.0, 0)]
(Background on this error at: https://sqlalche.me/e/20/gkpj)
2025-10-17 10:22:58.534 | ERROR    | app.core.exception_handler:global_exception_handler:14 - Traceback: Traceback (most recent call last):
  File "C:\Users\Raphael\AppData\Local\Programs\Python\Python311\Lib\site-packages\sqlalchemy\dialects\postgresql\asyncpg.py", line 545, in _prepare_and_execute
    self._rows = deque(await prepared_stmt.fetch(*parameters))
                       ^^^^^^^^^^^^^^^^^^^^^^^^^^^^^^^^^^^^^^
  File "C:\Users\Raphael\AppData\Local\Programs\Python\Python311\Lib\site-packages\asyncpg\prepared_stmt.py", line 176, in fetch
    data = await self.__bind_execute(args, 0, timeout)
           ^^^^^^^^^^^^^^^^^^^^^^^^^^^^^^^^^^^^^^^^^^^
  File "C:\Users\Raphael\AppData\Local\Programs\Python\Python311\Lib\site-packages\asyncpg\prepared_stmt.py", line 267, in __bind_execute
    data, status, _ = await self.__do_execute(
                      ^^^^^^^^^^^^^^^^^^^^^^^^
  File "C:\Users\Raphael\AppData\Local\Programs\Python\Python311\Lib\site-packages\asyncpg\prepared_stmt.py", line 256, in __do_execute
    return await executor(protocol)
           ^^^^^^^^^^^^^^^^^^^^^^^^
  File "asyncpg\\protocol\\protocol.pyx", line 206, in bind_execute
asyncpg.exceptions.NotNullViolationError: o valor nulo na coluna "store_id" da relação "customers" viola a restrição de não-nulo
DETAIL:  Registro que falhou contém (2, Raphael, 16996440178, raphaeldestefanobraga@gmail.com, null, null, null, 0, 0, 2025-10-17 10:22:58.422392, 2025-10-17 10:22:58.422392).

The above exception was the direct cause of the following exception:

Traceback (most recent call last):
  File "C:\Users\Raphael\AppData\Local\Programs\Python\Python311\Lib\site-packages\sqlalchemy\engine\base.py", line 1967, in _exec_single_context
    self.dialect.do_execute(
  File "C:\Users\Raphael\AppData\Local\Programs\Python\Python311\Lib\site-packages\sqlalchemy\engine\default.py", line 951, in do_execute
    cursor.execute(statement, parameters)
  File "C:\Users\Raphael\AppData\Local\Programs\Python\Python311\Lib\site-packages\sqlalchemy\dialects\postgresql\asyncpg.py", line 580, in execute
    self._adapt_connection.await_(
  File "C:\Users\Raphael\AppData\Local\Programs\Python\Python311\Lib\site-packages\sqlalchemy\util\_concurrency_py3k.py", line 132, in await_only
    return current.parent.switch(awaitable)  # type: ignore[no-any-return,attr-defined] # noqa: E501
           ^^^^^^^^^^^^^^^^^^^^^^^^^^^^^^^^
  File "C:\Users\Raphael\AppData\Local\Programs\Python\Python311\Lib\site-packages\sqlalchemy\util\_concurrency_py3k.py", line 196, in greenlet_spawn
    value = await result
            ^^^^^^^^^^^^
  File "C:\Users\Raphael\AppData\Local\Programs\Python\Python311\Lib\site-packages\sqlalchemy\dialects\postgresql\asyncpg.py", line 558, in _prepare_and_execute
    self._handle_exception(error)
  File "C:\Users\Raphael\AppData\Local\Programs\Python\Python311\Lib\site-packages\sqlalchemy\dialects\postgresql\asyncpg.py", line 508, in _handle_exception
    self._adapt_connection._handle_exception(error)
  File "C:\Users\Raphael\AppData\Local\Programs\Python\Python311\Lib\site-packages\sqlalchemy\dialects\postgresql\asyncpg.py", line 792, in _handle_exception
    raise translated_error from error
sqlalchemy.dialects.postgresql.asyncpg.AsyncAdapt_asyncpg_dbapi.IntegrityError: <class 'asyncpg.exceptions.NotNullViolationError'>: o valor nulo na coluna "store_id" da relação "customers" viola a restrição de não-nulo
DETAIL:  Registro que falhou contém (2, Raphael, 16996440178, raphaeldestefanobraga@gmail.com, null, null, null, 0, 0, 2025-10-17 10:22:58.422392, 2025-10-17 10:22:58.422392).

The above exception was the direct cause of the following exception:

Traceback (most recent call last):
  File "C:\Users\Raphael\AppData\Local\Programs\Python\Python311\Lib\site-packages\starlette\middleware\errors.py", line 164, in __call__
    await self.app(scope, receive, _send)
  File "C:\Users\Raphael\AppData\Local\Programs\Python\Python311\Lib\site-packages\starlette\middleware\cors.py", line 93, in __call__
    await self.simple_response(scope, receive, send, request_headers=headers)
  File "C:\Users\Raphael\AppData\Local\Programs\Python\Python311\Lib\site-packages\starlette\middleware\cors.py", line 144, in simple_response
    await self.app(scope, receive, send)
  File "C:\Users\Raphael\AppData\Local\Programs\Python\Python311\Lib\site-packages\starlette\middleware\base.py", line 182, in __call__
    with recv_stream, send_stream, collapse_excgroups():
  File "C:\Users\Raphael\AppData\Local\Programs\Python\Python311\Lib\contextlib.py", line 158, in __exit__
    self.gen.throw(typ, value, traceback)
  File "C:\Users\Raphael\AppData\Local\Programs\Python\Python311\Lib\site-packages\starlette\_utils.py", line 85, in collapse_excgroups
    raise exc
  File "C:\Users\Raphael\AppData\Local\Programs\Python\Python311\Lib\site-packages\starlette\middleware\base.py", line 184, in __call__
    response = await self.dispatch_func(request, call_next)
               ^^^^^^^^^^^^^^^^^^^^^^^^^^^^^^^^^^^^^^^^^^^^
  File "C:\Users\Raphael\Downloads\VRSales\api\main.py", line 41, in log_requests
    response = await call_next(request)
               ^^^^^^^^^^^^^^^^^^^^^^^^
  File "C:\Users\Raphael\AppData\Local\Programs\Python\Python311\Lib\site-packages\starlette\middleware\base.py", line 159, in call_next
    raise app_exc
  File "C:\Users\Raphael\AppData\Local\Programs\Python\Python311\Lib\site-packages\starlette\middleware\base.py", line 144, in coro
    await self.app(scope, receive_or_disconnect, send_no_error)
  File "C:\Users\Raphael\AppData\Local\Programs\Python\Python311\Lib\site-packages\starlette\middleware\exceptions.py", line 63, in __call__
    await wrap_app_handling_exceptions(self.app, conn)(scope, receive, send)
  File "C:\Users\Raphael\AppData\Local\Programs\Python\Python311\Lib\site-packages\starlette\_exception_handler.py", line 53, in wrapped_app
    raise exc
  File "C:\Users\Raphael\AppData\Local\Programs\Python\Python311\Lib\site-packages\starlette\_exception_handler.py", line 42, in wrapped_app
    await app(scope, receive, sender)
  File "C:\Users\Raphael\AppData\Local\Programs\Python\Python311\Lib\site-packages\fastapi\middleware\asyncexitstack.py", line 18, in __call__
    await self.app(scope, receive, send)
  File "C:\Users\Raphael\AppData\Local\Programs\Python\Python311\Lib\site-packages\starlette\routing.py", line 716, in __call__
    await self.middleware_stack(scope, receive, send)
  File "C:\Users\Raphael\AppData\Local\Programs\Python\Python311\Lib\site-packages\starlette\routing.py", line 736, in app
    await route.handle(scope, receive, send)
  File "C:\Users\Raphael\AppData\Local\Programs\Python\Python311\Lib\site-packages\starlette\routing.py", line 290, in handle
    await self.app(scope, receive, send)
  File "C:\Users\Raphael\AppData\Local\Programs\Python\Python311\Lib\site-packages\fastapi\routing.py", line 123, in app
    await wrap_app_handling_exceptions(app, request)(scope, receive, send)
  File "C:\Users\Raphael\AppData\Local\Programs\Python\Python311\Lib\site-packages\starlette\_exception_handler.py", line 53, in wrapped_app
    raise exc
  File "C:\Users\Raphael\AppData\Local\Programs\Python\Python311\Lib\site-packages\starlette\_exception_handler.py", line 42, in wrapped_app
    await app(scope, receive, sender)
  File "C:\Users\Raphael\AppData\Local\Programs\Python\Python311\Lib\site-packages\fastapi\routing.py", line 109, in app
    response = await f(request)
               ^^^^^^^^^^^^^^^^
  File "C:\Users\Raphael\AppData\Local\Programs\Python\Python311\Lib\site-packages\fastapi\routing.py", line 387, in app
    raw_response = await run_endpoint_function(
                   ^^^^^^^^^^^^^^^^^^^^^^^^^^^^
  File "C:\Users\Raphael\AppData\Local\Programs\Python\Python311\Lib\site-packages\fastapi\routing.py", line 288, in run_endpoint_function
    return await dependant.call(**values)
           ^^^^^^^^^^^^^^^^^^^^^^^^^^^^^^
  File "C:\Users\Raphael\Downloads\VRSales\api\app\api\endpoints\customers.py", line 28, in create_customer
    return await crud.customer.create(db=db, obj_in=customer_in, current_user=current_user)
           ^^^^^^^^^^^^^^^^^^^^^^^^^^^^^^^^^^^^^^^^^^^^^^^^^^^^^^^^^^^^^^^^^^^^^^^^^^^^^^^^
  File "C:\Users\Raphael\Downloads\VRSales\api\app\crud\base.py", line 56, in create
    await db.commit()
  File "C:\Users\Raphael\AppData\Local\Programs\Python\Python311\Lib\site-packages\sqlalchemy\ext\asyncio\session.py", line 1014, in commit
    await greenlet_spawn(self.sync_session.commit)
  File "C:\Users\Raphael\AppData\Local\Programs\Python\Python311\Lib\site-packages\sqlalchemy\util\_concurrency_py3k.py", line 203, in greenlet_spawn
    result = context.switch(value)
             ^^^^^^^^^^^^^^^^^^^^^
  File "C:\Users\Raphael\AppData\Local\Programs\Python\Python311\Lib\site-packages\sqlalchemy\orm\session.py", line 2032, in commit
    trans.commit(_to_root=True)
  File "<string>", line 2, in commit
  File "C:\Users\Raphael\AppData\Local\Programs\Python\Python311\Lib\site-packages\sqlalchemy\orm\state_changes.py", line 137, in _go
    ret_value = fn(self, *arg, **kw)
                ^^^^^^^^^^^^^^^^^^^^
  File "C:\Users\Raphael\AppData\Local\Programs\Python\Python311\Lib\site-packages\sqlalchemy\orm\session.py", line 1313, in commit
    self._prepare_impl()
  File "<string>", line 2, in _prepare_impl
  File "C:\Users\Raphael\AppData\Local\Programs\Python\Python311\Lib\site-packages\sqlalchemy\orm\state_changes.py", line 137, in _go
    ret_value = fn(self, *arg, **kw)
                ^^^^^^^^^^^^^^^^^^^^
  File "C:\Users\Raphael\AppData\Local\Programs\Python\Python311\Lib\site-packages\sqlalchemy\orm\session.py", line 1288, in _prepare_impl
    self.session.flush()
  File "C:\Users\Raphael\AppData\Local\Programs\Python\Python311\Lib\site-packages\sqlalchemy\orm\session.py", line 4345, in flush
    self._flush(objects)
  File "C:\Users\Raphael\AppData\Local\Programs\Python\Python311\Lib\site-packages\sqlalchemy\orm\session.py", line 4480, in _flush
    with util.safe_reraise():
  File "C:\Users\Raphael\AppData\Local\Programs\Python\Python311\Lib\site-packages\sqlalchemy\util\langhelpers.py", line 224, in __exit__
    raise exc_value.with_traceback(exc_tb)
  File "C:\Users\Raphael\AppData\Local\Programs\Python\Python311\Lib\site-packages\sqlalchemy\orm\session.py", line 4441, in _flush
    flush_context.execute()
  File "C:\Users\Raphael\AppData\Local\Programs\Python\Python311\Lib\site-packages\sqlalchemy\orm\unitofwork.py", line 466, in execute
    rec.execute(self)
  File "C:\Users\Raphael\AppData\Local\Programs\Python\Python311\Lib\site-packages\sqlalchemy\orm\unitofwork.py", line 642, in execute
    util.preloaded.orm_persistence.save_obj(
  File "C:\Users\Raphael\AppData\Local\Programs\Python\Python311\Lib\site-packages\sqlalchemy\orm\persistence.py", line 93, in save_obj
    _emit_insert_statements(
  File "C:\Users\Raphael\AppData\Local\Programs\Python\Python311\Lib\site-packages\sqlalchemy\orm\persistence.py", line 1233, in _emit_insert_statements
    result = connection.execute(
             ^^^^^^^^^^^^^^^^^^^
  File "C:\Users\Raphael\AppData\Local\Programs\Python\Python311\Lib\site-packages\sqlalchemy\engine\base.py", line 1419, in execute
    return meth(
           ^^^^^
  File "C:\Users\Raphael\AppData\Local\Programs\Python\Python311\Lib\site-packages\sqlalchemy\sql\elements.py", line 526, in _execute_on_connection
    return connection._execute_clauseelement(
           ^^^^^^^^^^^^^^^^^^^^^^^^^^^^^^^^^^
  File "C:\Users\Raphael\AppData\Local\Programs\Python\Python311\Lib\site-packages\sqlalchemy\engine\base.py", line 1641, in _execute_clauseelement
    ret = self._execute_context(
          ^^^^^^^^^^^^^^^^^^^^^^
  File "C:\Users\Raphael\AppData\Local\Programs\Python\Python311\Lib\site-packages\sqlalchemy\engine\base.py", line 1846, in _execute_context
    return self._exec_single_context(
           ^^^^^^^^^^^^^^^^^^^^^^^^^^
  File "C:\Users\Raphael\AppData\Local\Programs\Python\Python311\Lib\site-packages\sqlalchemy\engine\base.py", line 1986, in _exec_single_context
    self._handle_dbapi_exception(
  File "C:\Users\Raphael\AppData\Local\Programs\Python\Python311\Lib\site-packages\sqlalchemy\engine\base.py", line 2355, in _handle_dbapi_exception
    raise sqlalchemy_exception.with_traceback(exc_info[2]) from e
  File "C:\Users\Raphael\AppData\Local\Programs\Python\Python311\Lib\site-packages\sqlalchemy\engine\base.py", line 1967, in _exec_single_context
    self.dialect.do_execute(
  File "C:\Users\Raphael\AppData\Local\Programs\Python\Python311\Lib\site-packages\sqlalchemy\engine\default.py", line 951, in do_execute
    cursor.execute(statement, parameters)
  File "C:\Users\Raphael\AppData\Local\Programs\Python\Python311\Lib\site-packages\sqlalchemy\dialects\postgresql\asyncpg.py", line 580, in execute
    self._adapt_connection.await_(
  File "C:\Users\Raphael\AppData\Local\Programs\Python\Python311\Lib\site-packages\sqlalchemy\util\_concurrency_py3k.py", line 132, in await_only
    return current.parent.switch(awaitable)  # type: ignore[no-any-return,attr-defined] # noqa: E501
           ^^^^^^^^^^^^^^^^^^^^^^^^^^^^^^^^
  File "C:\Users\Raphael\AppData\Local\Programs\Python\Python311\Lib\site-packages\sqlalchemy\util\_concurrency_py3k.py", line 196, in greenlet_spawn
    value = await result
            ^^^^^^^^^^^^
  File "C:\Users\Raphael\AppData\Local\Programs\Python\Python311\Lib\site-packages\sqlalchemy\dialects\postgresql\asyncpg.py", line 558, in _prepare_and_execute
    self._handle_exception(error)
  File "C:\Users\Raphael\AppData\Local\Programs\Python\Python311\Lib\site-packages\sqlalchemy\dialects\postgresql\asyncpg.py", line 508, in _handle_exception
    self._adapt_connection._handle_exception(error)
  File "C:\Users\Raphael\AppData\Local\Programs\Python\Python311\Lib\site-packages\sqlalchemy\dialects\postgresql\asyncpg.py", line 792, in _handle_exception
    raise translated_error from error
sqlalchemy.exc.IntegrityError: (sqlalchemy.dialects.postgresql.asyncpg.IntegrityError) <class 'asyncpg.exceptions.NotNullViolationError'>: o valor nulo na coluna "store_id" da relação "customers" viola a restrição de não-nulo
DETAIL:  Registro que falhou contém (2, Raphael, 16996440178, raphaeldestefanobraga@gmail.com, null, null, null, 0, 0, 2025-10-17 10:22:58.422392, 2025-10-17 10:22:58.422392).
[SQL: INSERT INTO customers (full_name, phone_number, email, document_number, store_id, last_seen, total_spent, loyalty_points, created_at, updated_at) VALUES ($1::VARCHAR, $2::VARCHAR, $3::VARCHAR, $4::VARCHAR, $5::INTEGER, $6::TIMESTAMP WITHOUT TIME ZONE, $7::FLOAT, $8::INTEGER, now(), now()) RETURNING customers.id, customers.created_at, customers.updated_at]
[parameters: ('Raphael', '16996440178', 'raphaeldestefanobraga@gmail.com', None, None, None, 0.0, 0)]
(Background on this error at: https://sqlalche.me/e/20/gkpj)

2025-10-17 10:22:59.555 | ERROR    | app.core.exception_handler:global_exception_handler:12 - Erro inesperado na requisição: POST http://localhost:8000/api/v1/customers/
2025-10-17 10:22:59.555 | ERROR    | app.core.exception_handler:global_exception_handler:13 - Exceção: (sqlalchemy.dialects.postgresql.asyncpg.IntegrityError) <class 'asyncpg.exceptions.NotNullViolationError'>: o valor nulo na coluna "store_id" da relação "customers" viola a restrição de não-nulo
DETAIL:  Registro que falhou contém (3, Raphael, 16996440178, raphaeldestefanobraga@gmail.com, null, null, null, 0, 0, 2025-10-17 10:22:59.556845, 2025-10-17 10:22:59.556845).
[SQL: INSERT INTO customers (full_name, phone_number, email, document_number, store_id, last_seen, total_spent, loyalty_points, created_at, updated_at) VALUES ($1::VARCHAR, $2::VARCHAR, $3::VARCHAR, $4::VARCHAR, $5::INTEGER, $6::TIMESTAMP WITHOUT TIME ZONE, $7::FLOAT, $8::INTEGER, now(), now()) RETURNING customers.id, customers.created_at, customers.updated_at]
[parameters: ('Raphael', '16996440178', 'raphaeldestefanobraga@gmail.com', None, None, None, 0.0, 0)]
(Background on this error at: https://sqlalche.me/e/20/gkpj)
2025-10-17 10:22:59.559 | ERROR    | app.core.exception_handler:global_exception_handler:14 - Traceback: Traceback (most recent call last):
  File "C:\Users\Raphael\AppData\Local\Programs\Python\Python311\Lib\site-packages\sqlalchemy\dialects\postgresql\asyncpg.py", line 545, in _prepare_and_execute
    self._rows = deque(await prepared_stmt.fetch(*parameters))
                       ^^^^^^^^^^^^^^^^^^^^^^^^^^^^^^^^^^^^^^
  File "C:\Users\Raphael\AppData\Local\Programs\Python\Python311\Lib\site-packages\asyncpg\prepared_stmt.py", line 176, in fetch
    data = await self.__bind_execute(args, 0, timeout)
           ^^^^^^^^^^^^^^^^^^^^^^^^^^^^^^^^^^^^^^^^^^^
  File "C:\Users\Raphael\AppData\Local\Programs\Python\Python311\Lib\site-packages\asyncpg\prepared_stmt.py", line 267, in __bind_execute
    data, status, _ = await self.__do_execute(
                      ^^^^^^^^^^^^^^^^^^^^^^^^
  File "C:\Users\Raphael\AppData\Local\Programs\Python\Python311\Lib\site-packages\asyncpg\prepared_stmt.py", line 256, in __do_execute
    return await executor(protocol)
           ^^^^^^^^^^^^^^^^^^^^^^^^
  File "asyncpg\\protocol\\protocol.pyx", line 206, in bind_execute
asyncpg.exceptions.NotNullViolationError: o valor nulo na coluna "store_id" da relação "customers" viola a restrição de não-nulo
DETAIL:  Registro que falhou contém (3, Raphael, 16996440178, raphaeldestefanobraga@gmail.com, null, null, null, 0, 0, 2025-10-17 10:22:59.556845, 2025-10-17 10:22:59.556845).

The above exception was the direct cause of the following exception:

Traceback (most recent call last):
  File "C:\Users\Raphael\AppData\Local\Programs\Python\Python311\Lib\site-packages\sqlalchemy\engine\base.py", line 1967, in _exec_single_context
    self.dialect.do_execute(
  File "C:\Users\Raphael\AppData\Local\Programs\Python\Python311\Lib\site-packages\sqlalchemy\engine\default.py", line 951, in do_execute
    cursor.execute(statement, parameters)
  File "C:\Users\Raphael\AppData\Local\Programs\Python\Python311\Lib\site-packages\sqlalchemy\dialects\postgresql\asyncpg.py", line 580, in execute
    self._adapt_connection.await_(
  File "C:\Users\Raphael\AppData\Local\Programs\Python\Python311\Lib\site-packages\sqlalchemy\util\_concurrency_py3k.py", line 132, in await_only
    return current.parent.switch(awaitable)  # type: ignore[no-any-return,attr-defined] # noqa: E501
           ^^^^^^^^^^^^^^^^^^^^^^^^^^^^^^^^
  File "C:\Users\Raphael\AppData\Local\Programs\Python\Python311\Lib\site-packages\sqlalchemy\util\_concurrency_py3k.py", line 196, in greenlet_spawn
    value = await result
            ^^^^^^^^^^^^
  File "C:\Users\Raphael\AppData\Local\Programs\Python\Python311\Lib\site-packages\sqlalchemy\dialects\postgresql\asyncpg.py", line 558, in _prepare_and_execute
    self._handle_exception(error)
  File "C:\Users\Raphael\AppData\Local\Programs\Python\Python311\Lib\site-packages\sqlalchemy\dialects\postgresql\asyncpg.py", line 508, in _handle_exception
    self._adapt_connection._handle_exception(error)
  File "C:\Users\Raphael\AppData\Local\Programs\Python\Python311\Lib\site-packages\sqlalchemy\dialects\postgresql\asyncpg.py", line 792, in _handle_exception
    raise translated_error from error
sqlalchemy.dialects.postgresql.asyncpg.AsyncAdapt_asyncpg_dbapi.IntegrityError: <class 'asyncpg.exceptions.NotNullViolationError'>: o valor nulo na coluna "store_id" da relação "customers" viola a restrição de não-nulo
DETAIL:  Registro que falhou contém (3, Raphael, 16996440178, raphaeldestefanobraga@gmail.com, null, null, null, 0, 0, 2025-10-17 10:22:59.556845, 2025-10-17 10:22:59.556845).

The above exception was the direct cause of the following exception:

Traceback (most recent call last):
  File "C:\Users\Raphael\AppData\Local\Programs\Python\Python311\Lib\site-packages\starlette\middleware\errors.py", line 164, in __call__
    await self.app(scope, receive, _send)
  File "C:\Users\Raphael\AppData\Local\Programs\Python\Python311\Lib\site-packages\starlette\middleware\cors.py", line 93, in __call__
    await self.simple_response(scope, receive, send, request_headers=headers)
  File "C:\Users\Raphael\AppData\Local\Programs\Python\Python311\Lib\site-packages\starlette\middleware\cors.py", line 144, in simple_response
    await self.app(scope, receive, send)
  File "C:\Users\Raphael\AppData\Local\Programs\Python\Python311\Lib\site-packages\starlette\middleware\base.py", line 182, in __call__
    with recv_stream, send_stream, collapse_excgroups():
  File "C:\Users\Raphael\AppData\Local\Programs\Python\Python311\Lib\contextlib.py", line 158, in __exit__
    self.gen.throw(typ, value, traceback)
  File "C:\Users\Raphael\AppData\Local\Programs\Python\Python311\Lib\site-packages\starlette\_utils.py", line 85, in collapse_excgroups
    raise exc
  File "C:\Users\Raphael\AppData\Local\Programs\Python\Python311\Lib\site-packages\starlette\middleware\base.py", line 184, in __call__
    response = await self.dispatch_func(request, call_next)
               ^^^^^^^^^^^^^^^^^^^^^^^^^^^^^^^^^^^^^^^^^^^^
  File "C:\Users\Raphael\Downloads\VRSales\api\main.py", line 41, in log_requests
    response = await call_next(request)
               ^^^^^^^^^^^^^^^^^^^^^^^^
  File "C:\Users\Raphael\AppData\Local\Programs\Python\Python311\Lib\site-packages\starlette\middleware\base.py", line 159, in call_next
    raise app_exc
  File "C:\Users\Raphael\AppData\Local\Programs\Python\Python311\Lib\site-packages\starlette\middleware\base.py", line 144, in coro
    await self.app(scope, receive_or_disconnect, send_no_error)
  File "C:\Users\Raphael\AppData\Local\Programs\Python\Python311\Lib\site-packages\starlette\middleware\exceptions.py", line 63, in __call__
    await wrap_app_handling_exceptions(self.app, conn)(scope, receive, send)
  File "C:\Users\Raphael\AppData\Local\Programs\Python\Python311\Lib\site-packages\starlette\_exception_handler.py", line 53, in wrapped_app
    raise exc
  File "C:\Users\Raphael\AppData\Local\Programs\Python\Python311\Lib\site-packages\starlette\_exception_handler.py", line 42, in wrapped_app
    await app(scope, receive, sender)
  File "C:\Users\Raphael\AppData\Local\Programs\Python\Python311\Lib\site-packages\fastapi\middleware\asyncexitstack.py", line 18, in __call__
    await self.app(scope, receive, send)
  File "C:\Users\Raphael\AppData\Local\Programs\Python\Python311\Lib\site-packages\starlette\routing.py", line 716, in __call__
    await self.middleware_stack(scope, receive, send)
  File "C:\Users\Raphael\AppData\Local\Programs\Python\Python311\Lib\site-packages\starlette\routing.py", line 736, in app
    await route.handle(scope, receive, send)
  File "C:\Users\Raphael\AppData\Local\Programs\Python\Python311\Lib\site-packages\starlette\routing.py", line 290, in handle
    await self.app(scope, receive, send)
  File "C:\Users\Raphael\AppData\Local\Programs\Python\Python311\Lib\site-packages\fastapi\routing.py", line 123, in app
    await wrap_app_handling_exceptions(app, request)(scope, receive, send)
  File "C:\Users\Raphael\AppData\Local\Programs\Python\Python311\Lib\site-packages\starlette\_exception_handler.py", line 53, in wrapped_app
    raise exc
  File "C:\Users\Raphael\AppData\Local\Programs\Python\Python311\Lib\site-packages\starlette\_exception_handler.py", line 42, in wrapped_app
    await app(scope, receive, sender)
  File "C:\Users\Raphael\AppData\Local\Programs\Python\Python311\Lib\site-packages\fastapi\routing.py", line 109, in app
    response = await f(request)
               ^^^^^^^^^^^^^^^^
  File "C:\Users\Raphael\AppData\Local\Programs\Python\Python311\Lib\site-packages\fastapi\routing.py", line 387, in app
    raw_response = await run_endpoint_function(
                   ^^^^^^^^^^^^^^^^^^^^^^^^^^^^
  File "C:\Users\Raphael\AppData\Local\Programs\Python\Python311\Lib\site-packages\fastapi\routing.py", line 288, in run_endpoint_function
    return await dependant.call(**values)
           ^^^^^^^^^^^^^^^^^^^^^^^^^^^^^^
  File "C:\Users\Raphael\Downloads\VRSales\api\app\api\endpoints\customers.py", line 28, in create_customer
    return await crud.customer.create(db=db, obj_in=customer_in, current_user=current_user)
           ^^^^^^^^^^^^^^^^^^^^^^^^^^^^^^^^^^^^^^^^^^^^^^^^^^^^^^^^^^^^^^^^^^^^^^^^^^^^^^^^
  File "C:\Users\Raphael\Downloads\VRSales\api\app\crud\base.py", line 56, in create
    await db.commit()
  File "C:\Users\Raphael\AppData\Local\Programs\Python\Python311\Lib\site-packages\sqlalchemy\ext\asyncio\session.py", line 1014, in commit
    await greenlet_spawn(self.sync_session.commit)
  File "C:\Users\Raphael\AppData\Local\Programs\Python\Python311\Lib\site-packages\sqlalchemy\util\_concurrency_py3k.py", line 203, in greenlet_spawn
    result = context.switch(value)
             ^^^^^^^^^^^^^^^^^^^^^
  File "C:\Users\Raphael\AppData\Local\Programs\Python\Python311\Lib\site-packages\sqlalchemy\orm\session.py", line 2032, in commit
    trans.commit(_to_root=True)
  File "<string>", line 2, in commit
  File "C:\Users\Raphael\AppData\Local\Programs\Python\Python311\Lib\site-packages\sqlalchemy\orm\state_changes.py", line 137, in _go
    ret_value = fn(self, *arg, **kw)
                ^^^^^^^^^^^^^^^^^^^^
  File "C:\Users\Raphael\AppData\Local\Programs\Python\Python311\Lib\site-packages\sqlalchemy\orm\session.py", line 1313, in commit
    self._prepare_impl()
  File "<string>", line 2, in _prepare_impl
  File "C:\Users\Raphael\AppData\Local\Programs\Python\Python311\Lib\site-packages\sqlalchemy\orm\state_changes.py", line 137, in _go
    ret_value = fn(self, *arg, **kw)
                ^^^^^^^^^^^^^^^^^^^^
  File "C:\Users\Raphael\AppData\Local\Programs\Python\Python311\Lib\site-packages\sqlalchemy\orm\session.py", line 1288, in _prepare_impl
    self.session.flush()
  File "C:\Users\Raphael\AppData\Local\Programs\Python\Python311\Lib\site-packages\sqlalchemy\orm\session.py", line 4345, in flush
    self._flush(objects)
  File "C:\Users\Raphael\AppData\Local\Programs\Python\Python311\Lib\site-packages\sqlalchemy\orm\session.py", line 4480, in _flush
    with util.safe_reraise():
  File "C:\Users\Raphael\AppData\Local\Programs\Python\Python311\Lib\site-packages\sqlalchemy\util\langhelpers.py", line 224, in __exit__
    raise exc_value.with_traceback(exc_tb)
  File "C:\Users\Raphael\AppData\Local\Programs\Python\Python311\Lib\site-packages\sqlalchemy\orm\session.py", line 4441, in _flush
    flush_context.execute()
  File "C:\Users\Raphael\AppData\Local\Programs\Python\Python311\Lib\site-packages\sqlalchemy\orm\unitofwork.py", line 466, in execute
    rec.execute(self)
  File "C:\Users\Raphael\AppData\Local\Programs\Python\Python311\Lib\site-packages\sqlalchemy\orm\unitofwork.py", line 642, in execute
    util.preloaded.orm_persistence.save_obj(
  File "C:\Users\Raphael\AppData\Local\Programs\Python\Python311\Lib\site-packages\sqlalchemy\orm\persistence.py", line 93, in save_obj
    _emit_insert_statements(
  File "C:\Users\Raphael\AppData\Local\Programs\Python\Python311\Lib\site-packages\sqlalchemy\orm\persistence.py", line 1233, in _emit_insert_statements
    result = connection.execute(
             ^^^^^^^^^^^^^^^^^^^
  File "C:\Users\Raphael\AppData\Local\Programs\Python\Python311\Lib\site-packages\sqlalchemy\engine\base.py", line 1419, in execute
    return meth(
           ^^^^^
  File "C:\Users\Raphael\AppData\Local\Programs\Python\Python311\Lib\site-packages\sqlalchemy\sql\elements.py", line 526, in _execute_on_connection
    return connection._execute_clauseelement(
           ^^^^^^^^^^^^^^^^^^^^^^^^^^^^^^^^^^
  File "C:\Users\Raphael\AppData\Local\Programs\Python\Python311\Lib\site-packages\sqlalchemy\engine\base.py", line 1641, in _execute_clauseelement
    ret = self._execute_context(
          ^^^^^^^^^^^^^^^^^^^^^^
  File "C:\Users\Raphael\AppData\Local\Programs\Python\Python311\Lib\site-packages\sqlalchemy\engine\base.py", line 1846, in _execute_context
    return self._exec_single_context(
           ^^^^^^^^^^^^^^^^^^^^^^^^^^
  File "C:\Users\Raphael\AppData\Local\Programs\Python\Python311\Lib\site-packages\sqlalchemy\engine\base.py", line 1986, in _exec_single_context
    self._handle_dbapi_exception(
  File "C:\Users\Raphael\AppData\Local\Programs\Python\Python311\Lib\site-packages\sqlalchemy\engine\base.py", line 2355, in _handle_dbapi_exception
    raise sqlalchemy_exception.with_traceback(exc_info[2]) from e
  File "C:\Users\Raphael\AppData\Local\Programs\Python\Python311\Lib\site-packages\sqlalchemy\engine\base.py", line 1967, in _exec_single_context
    self.dialect.do_execute(
  File "C:\Users\Raphael\AppData\Local\Programs\Python\Python311\Lib\site-packages\sqlalchemy\engine\default.py", line 951, in do_execute
    cursor.execute(statement, parameters)
  File "C:\Users\Raphael\AppData\Local\Programs\Python\Python311\Lib\site-packages\sqlalchemy\dialects\postgresql\asyncpg.py", line 580, in execute
    self._adapt_connection.await_(
  File "C:\Users\Raphael\AppData\Local\Programs\Python\Python311\Lib\site-packages\sqlalchemy\util\_concurrency_py3k.py", line 132, in await_only
    return current.parent.switch(awaitable)  # type: ignore[no-any-return,attr-defined] # noqa: E501
           ^^^^^^^^^^^^^^^^^^^^^^^^^^^^^^^^
  File "C:\Users\Raphael\AppData\Local\Programs\Python\Python311\Lib\site-packages\sqlalchemy\util\_concurrency_py3k.py", line 196, in greenlet_spawn
    value = await result
            ^^^^^^^^^^^^
  File "C:\Users\Raphael\AppData\Local\Programs\Python\Python311\Lib\site-packages\sqlalchemy\dialects\postgresql\asyncpg.py", line 558, in _prepare_and_execute
    self._handle_exception(error)
  File "C:\Users\Raphael\AppData\Local\Programs\Python\Python311\Lib\site-packages\sqlalchemy\dialects\postgresql\asyncpg.py", line 508, in _handle_exception
    self._adapt_connection._handle_exception(error)
  File "C:\Users\Raphael\AppData\Local\Programs\Python\Python311\Lib\site-packages\sqlalchemy\dialects\postgresql\asyncpg.py", line 792, in _handle_exception
    raise translated_error from error
sqlalchemy.exc.IntegrityError: (sqlalchemy.dialects.postgresql.asyncpg.IntegrityError) <class 'asyncpg.exceptions.NotNullViolationError'>: o valor nulo na coluna "store_id" da relação "customers" viola a restrição de não-nulo
DETAIL:  Registro que falhou contém (3, Raphael, 16996440178, raphaeldestefanobraga@gmail.com, null, null, null, 0, 0, 2025-10-17 10:22:59.556845, 2025-10-17 10:22:59.556845).
[SQL: INSERT INTO customers (full_name, phone_number, email, document_number, store_id, last_seen, total_spent, loyalty_points, created_at, updated_at) VALUES ($1::VARCHAR, $2::VARCHAR, $3::VARCHAR, $4::VARCHAR, $5::INTEGER, $6::TIMESTAMP WITHOUT TIME ZONE, $7::FLOAT, $8::INTEGER, now(), now()) RETURNING customers.id, customers.created_at, customers.updated_at]
[parameters: ('Raphael', '16996440178', 'raphaeldestefanobraga@gmail.com', None, None, None, 0.0, 0)]
(Background on this error at: https://sqlalche.me/e/20/gkpj)

2025-10-17 10:23:02.190 | ERROR    | app.core.exception_handler:global_exception_handler:12 - Erro inesperado na requisição: POST http://localhost:8000/api/v1/customers/
2025-10-17 10:23:02.190 | ERROR    | app.core.exception_handler:global_exception_handler:13 - Exceção: (sqlalchemy.dialects.postgresql.asyncpg.IntegrityError) <class 'asyncpg.exceptions.NotNullViolationError'>: o valor nulo na coluna "store_id" da relação "customers" viola a restrição de não-nulo
DETAIL:  Registro que falhou contém (4, Raphael, 16996440178, raphaeldestefanobraga@gmail.com, null, null, null, 0, 0, 2025-10-17 10:23:02.196927, 2025-10-17 10:23:02.196927).
[SQL: INSERT INTO customers (full_name, phone_number, email, document_number, store_id, last_seen, total_spent, loyalty_points, created_at, updated_at) VALUES ($1::VARCHAR, $2::VARCHAR, $3::VARCHAR, $4::VARCHAR, $5::INTEGER, $6::TIMESTAMP WITHOUT TIME ZONE, $7::FLOAT, $8::INTEGER, now(), now()) RETURNING customers.id, customers.created_at, customers.updated_at]
[parameters: ('Raphael', '16996440178', 'raphaeldestefanobraga@gmail.com', None, None, None, 0.0, 0)]
(Background on this error at: https://sqlalche.me/e/20/gkpj)
2025-10-17 10:23:02.205 | ERROR    | app.core.exception_handler:global_exception_handler:14 - Traceback: Traceback (most recent call last):
  File "C:\Users\Raphael\AppData\Local\Programs\Python\Python311\Lib\site-packages\sqlalchemy\dialects\postgresql\asyncpg.py", line 545, in _prepare_and_execute
    self._rows = deque(await prepared_stmt.fetch(*parameters))
                       ^^^^^^^^^^^^^^^^^^^^^^^^^^^^^^^^^^^^^^
  File "C:\Users\Raphael\AppData\Local\Programs\Python\Python311\Lib\site-packages\asyncpg\prepared_stmt.py", line 176, in fetch
    data = await self.__bind_execute(args, 0, timeout)
           ^^^^^^^^^^^^^^^^^^^^^^^^^^^^^^^^^^^^^^^^^^^
  File "C:\Users\Raphael\AppData\Local\Programs\Python\Python311\Lib\site-packages\asyncpg\prepared_stmt.py", line 267, in __bind_execute
    data, status, _ = await self.__do_execute(
                      ^^^^^^^^^^^^^^^^^^^^^^^^
  File "C:\Users\Raphael\AppData\Local\Programs\Python\Python311\Lib\site-packages\asyncpg\prepared_stmt.py", line 256, in __do_execute
    return await executor(protocol)
           ^^^^^^^^^^^^^^^^^^^^^^^^
  File "asyncpg\\protocol\\protocol.pyx", line 206, in bind_execute
asyncpg.exceptions.NotNullViolationError: o valor nulo na coluna "store_id" da relação "customers" viola a restrição de não-nulo
DETAIL:  Registro que falhou contém (4, Raphael, 16996440178, raphaeldestefanobraga@gmail.com, null, null, null, 0, 0, 2025-10-17 10:23:02.196927, 2025-10-17 10:23:02.196927).

The above exception was the direct cause of the following exception:

Traceback (most recent call last):
  File "C:\Users\Raphael\AppData\Local\Programs\Python\Python311\Lib\site-packages\sqlalchemy\engine\base.py", line 1967, in _exec_single_context
    self.dialect.do_execute(
  File "C:\Users\Raphael\AppData\Local\Programs\Python\Python311\Lib\site-packages\sqlalchemy\engine\default.py", line 951, in do_execute
    cursor.execute(statement, parameters)
  File "C:\Users\Raphael\AppData\Local\Programs\Python\Python311\Lib\site-packages\sqlalchemy\dialects\postgresql\asyncpg.py", line 580, in execute
    self._adapt_connection.await_(
  File "C:\Users\Raphael\AppData\Local\Programs\Python\Python311\Lib\site-packages\sqlalchemy\util\_concurrency_py3k.py", line 132, in await_only
    return current.parent.switch(awaitable)  # type: ignore[no-any-return,attr-defined] # noqa: E501
           ^^^^^^^^^^^^^^^^^^^^^^^^^^^^^^^^
  File "C:\Users\Raphael\AppData\Local\Programs\Python\Python311\Lib\site-packages\sqlalchemy\util\_concurrency_py3k.py", line 196, in greenlet_spawn
    value = await result
            ^^^^^^^^^^^^
  File "C:\Users\Raphael\AppData\Local\Programs\Python\Python311\Lib\site-packages\sqlalchemy\dialects\postgresql\asyncpg.py", line 558, in _prepare_and_execute
    self._handle_exception(error)
  File "C:\Users\Raphael\AppData\Local\Programs\Python\Python311\Lib\site-packages\sqlalchemy\dialects\postgresql\asyncpg.py", line 508, in _handle_exception
    self._adapt_connection._handle_exception(error)
  File "C:\Users\Raphael\AppData\Local\Programs\Python\Python311\Lib\site-packages\sqlalchemy\dialects\postgresql\asyncpg.py", line 792, in _handle_exception
    raise translated_error from error
sqlalchemy.dialects.postgresql.asyncpg.AsyncAdapt_asyncpg_dbapi.IntegrityError: <class 'asyncpg.exceptions.NotNullViolationError'>: o valor nulo na coluna "store_id" da relação "customers" viola a restrição de não-nulo
DETAIL:  Registro que falhou contém (4, Raphael, 16996440178, raphaeldestefanobraga@gmail.com, null, null, null, 0, 0, 2025-10-17 10:23:02.196927, 2025-10-17 10:23:02.196927).

The above exception was the direct cause of the following exception:

Traceback (most recent call last):
  File "C:\Users\Raphael\AppData\Local\Programs\Python\Python311\Lib\site-packages\starlette\middleware\errors.py", line 164, in __call__
    await self.app(scope, receive, _send)
  File "C:\Users\Raphael\AppData\Local\Programs\Python\Python311\Lib\site-packages\starlette\middleware\cors.py", line 93, in __call__
    await self.simple_response(scope, receive, send, request_headers=headers)
  File "C:\Users\Raphael\AppData\Local\Programs\Python\Python311\Lib\site-packages\starlette\middleware\cors.py", line 144, in simple_response
    await self.app(scope, receive, send)
  File "C:\Users\Raphael\AppData\Local\Programs\Python\Python311\Lib\site-packages\starlette\middleware\base.py", line 182, in __call__
    with recv_stream, send_stream, collapse_excgroups():
  File "C:\Users\Raphael\AppData\Local\Programs\Python\Python311\Lib\contextlib.py", line 158, in __exit__
    self.gen.throw(typ, value, traceback)
  File "C:\Users\Raphael\AppData\Local\Programs\Python\Python311\Lib\site-packages\starlette\_utils.py", line 85, in collapse_excgroups
    raise exc
  File "C:\Users\Raphael\AppData\Local\Programs\Python\Python311\Lib\site-packages\starlette\middleware\base.py", line 184, in __call__
    response = await self.dispatch_func(request, call_next)
               ^^^^^^^^^^^^^^^^^^^^^^^^^^^^^^^^^^^^^^^^^^^^
  File "C:\Users\Raphael\Downloads\VRSales\api\main.py", line 41, in log_requests
    response = await call_next(request)
               ^^^^^^^^^^^^^^^^^^^^^^^^
  File "C:\Users\Raphael\AppData\Local\Programs\Python\Python311\Lib\site-packages\starlette\middleware\base.py", line 159, in call_next
    raise app_exc
  File "C:\Users\Raphael\AppData\Local\Programs\Python\Python311\Lib\site-packages\starlette\middleware\base.py", line 144, in coro
    await self.app(scope, receive_or_disconnect, send_no_error)
  File "C:\Users\Raphael\AppData\Local\Programs\Python\Python311\Lib\site-packages\starlette\middleware\exceptions.py", line 63, in __call__
    await wrap_app_handling_exceptions(self.app, conn)(scope, receive, send)
  File "C:\Users\Raphael\AppData\Local\Programs\Python\Python311\Lib\site-packages\starlette\_exception_handler.py", line 53, in wrapped_app
    raise exc
  File "C:\Users\Raphael\AppData\Local\Programs\Python\Python311\Lib\site-packages\starlette\_exception_handler.py", line 42, in wrapped_app
    await app(scope, receive, sender)
  File "C:\Users\Raphael\AppData\Local\Programs\Python\Python311\Lib\site-packages\fastapi\middleware\asyncexitstack.py", line 18, in __call__
    await self.app(scope, receive, send)
  File "C:\Users\Raphael\AppData\Local\Programs\Python\Python311\Lib\site-packages\starlette\routing.py", line 716, in __call__
    await self.middleware_stack(scope, receive, send)
  File "C:\Users\Raphael\AppData\Local\Programs\Python\Python311\Lib\site-packages\starlette\routing.py", line 736, in app
    await route.handle(scope, receive, send)
  File "C:\Users\Raphael\AppData\Local\Programs\Python\Python311\Lib\site-packages\starlette\routing.py", line 290, in handle
    await self.app(scope, receive, send)
  File "C:\Users\Raphael\AppData\Local\Programs\Python\Python311\Lib\site-packages\fastapi\routing.py", line 123, in app
    await wrap_app_handling_exceptions(app, request)(scope, receive, send)
  File "C:\Users\Raphael\AppData\Local\Programs\Python\Python311\Lib\site-packages\starlette\_exception_handler.py", line 53, in wrapped_app
    raise exc
  File "C:\Users\Raphael\AppData\Local\Programs\Python\Python311\Lib\site-packages\starlette\_exception_handler.py", line 42, in wrapped_app
    await app(scope, receive, sender)
  File "C:\Users\Raphael\AppData\Local\Programs\Python\Python311\Lib\site-packages\fastapi\routing.py", line 109, in app
    response = await f(request)
               ^^^^^^^^^^^^^^^^
  File "C:\Users\Raphael\AppData\Local\Programs\Python\Python311\Lib\site-packages\fastapi\routing.py", line 387, in app
    raw_response = await run_endpoint_function(
                   ^^^^^^^^^^^^^^^^^^^^^^^^^^^^
  File "C:\Users\Raphael\AppData\Local\Programs\Python\Python311\Lib\site-packages\fastapi\routing.py", line 288, in run_endpoint_function
    return await dependant.call(**values)
           ^^^^^^^^^^^^^^^^^^^^^^^^^^^^^^
  File "C:\Users\Raphael\Downloads\VRSales\api\app\api\endpoints\customers.py", line 28, in create_customer
    return await crud.customer.create(db=db, obj_in=customer_in, current_user=current_user)
           ^^^^^^^^^^^^^^^^^^^^^^^^^^^^^^^^^^^^^^^^^^^^^^^^^^^^^^^^^^^^^^^^^^^^^^^^^^^^^^^^
  File "C:\Users\Raphael\Downloads\VRSales\api\app\crud\base.py", line 56, in create
    await db.commit()
  File "C:\Users\Raphael\AppData\Local\Programs\Python\Python311\Lib\site-packages\sqlalchemy\ext\asyncio\session.py", line 1014, in commit
    await greenlet_spawn(self.sync_session.commit)
  File "C:\Users\Raphael\AppData\Local\Programs\Python\Python311\Lib\site-packages\sqlalchemy\util\_concurrency_py3k.py", line 203, in greenlet_spawn
    result = context.switch(value)
             ^^^^^^^^^^^^^^^^^^^^^
  File "C:\Users\Raphael\AppData\Local\Programs\Python\Python311\Lib\site-packages\sqlalchemy\orm\session.py", line 2032, in commit
    trans.commit(_to_root=True)
  File "<string>", line 2, in commit
  File "C:\Users\Raphael\AppData\Local\Programs\Python\Python311\Lib\site-packages\sqlalchemy\orm\state_changes.py", line 137, in _go
    ret_value = fn(self, *arg, **kw)
                ^^^^^^^^^^^^^^^^^^^^
  File "C:\Users\Raphael\AppData\Local\Programs\Python\Python311\Lib\site-packages\sqlalchemy\orm\session.py", line 1313, in commit
    self._prepare_impl()
  File "<string>", line 2, in _prepare_impl
  File "C:\Users\Raphael\AppData\Local\Programs\Python\Python311\Lib\site-packages\sqlalchemy\orm\state_changes.py", line 137, in _go
    ret_value = fn(self, *arg, **kw)
                ^^^^^^^^^^^^^^^^^^^^
  File "C:\Users\Raphael\AppData\Local\Programs\Python\Python311\Lib\site-packages\sqlalchemy\orm\session.py", line 1288, in _prepare_impl
    self.session.flush()
  File "C:\Users\Raphael\AppData\Local\Programs\Python\Python311\Lib\site-packages\sqlalchemy\orm\session.py", line 4345, in flush
    self._flush(objects)
  File "C:\Users\Raphael\AppData\Local\Programs\Python\Python311\Lib\site-packages\sqlalchemy\orm\session.py", line 4480, in _flush
    with util.safe_reraise():
  File "C:\Users\Raphael\AppData\Local\Programs\Python\Python311\Lib\site-packages\sqlalchemy\util\langhelpers.py", line 224, in __exit__
    raise exc_value.with_traceback(exc_tb)
  File "C:\Users\Raphael\AppData\Local\Programs\Python\Python311\Lib\site-packages\sqlalchemy\orm\session.py", line 4441, in _flush
    flush_context.execute()
  File "C:\Users\Raphael\AppData\Local\Programs\Python\Python311\Lib\site-packages\sqlalchemy\orm\unitofwork.py", line 466, in execute
    rec.execute(self)
  File "C:\Users\Raphael\AppData\Local\Programs\Python\Python311\Lib\site-packages\sqlalchemy\orm\unitofwork.py", line 642, in execute
    util.preloaded.orm_persistence.save_obj(
  File "C:\Users\Raphael\AppData\Local\Programs\Python\Python311\Lib\site-packages\sqlalchemy\orm\persistence.py", line 93, in save_obj
    _emit_insert_statements(
  File "C:\Users\Raphael\AppData\Local\Programs\Python\Python311\Lib\site-packages\sqlalchemy\orm\persistence.py", line 1233, in _emit_insert_statements
    result = connection.execute(
             ^^^^^^^^^^^^^^^^^^^
  File "C:\Users\Raphael\AppData\Local\Programs\Python\Python311\Lib\site-packages\sqlalchemy\engine\base.py", line 1419, in execute
    return meth(
           ^^^^^
  File "C:\Users\Raphael\AppData\Local\Programs\Python\Python311\Lib\site-packages\sqlalchemy\sql\elements.py", line 526, in _execute_on_connection
    return connection._execute_clauseelement(
           ^^^^^^^^^^^^^^^^^^^^^^^^^^^^^^^^^^
  File "C:\Users\Raphael\AppData\Local\Programs\Python\Python311\Lib\site-packages\sqlalchemy\engine\base.py", line 1641, in _execute_clauseelement
    ret = self._execute_context(
          ^^^^^^^^^^^^^^^^^^^^^^
  File "C:\Users\Raphael\AppData\Local\Programs\Python\Python311\Lib\site-packages\sqlalchemy\engine\base.py", line 1846, in _execute_context
    return self._exec_single_context(
           ^^^^^^^^^^^^^^^^^^^^^^^^^^
  File "C:\Users\Raphael\AppData\Local\Programs\Python\Python311\Lib\site-packages\sqlalchemy\engine\base.py", line 1986, in _exec_single_context
    self._handle_dbapi_exception(
  File "C:\Users\Raphael\AppData\Local\Programs\Python\Python311\Lib\site-packages\sqlalchemy\engine\base.py", line 2355, in _handle_dbapi_exception
    raise sqlalchemy_exception.with_traceback(exc_info[2]) from e
  File "C:\Users\Raphael\AppData\Local\Programs\Python\Python311\Lib\site-packages\sqlalchemy\engine\base.py", line 1967, in _exec_single_context
    self.dialect.do_execute(
  File "C:\Users\Raphael\AppData\Local\Programs\Python\Python311\Lib\site-packages\sqlalchemy\engine\default.py", line 951, in do_execute
    cursor.execute(statement, parameters)
  File "C:\Users\Raphael\AppData\Local\Programs\Python\Python311\Lib\site-packages\sqlalchemy\dialects\postgresql\asyncpg.py", line 580, in execute
    self._adapt_connection.await_(
  File "C:\Users\Raphael\AppData\Local\Programs\Python\Python311\Lib\site-packages\sqlalchemy\util\_concurrency_py3k.py", line 132, in await_only
    return current.parent.switch(awaitable)  # type: ignore[no-any-return,attr-defined] # noqa: E501
           ^^^^^^^^^^^^^^^^^^^^^^^^^^^^^^^^
  File "C:\Users\Raphael\AppData\Local\Programs\Python\Python311\Lib\site-packages\sqlalchemy\util\_concurrency_py3k.py", line 196, in greenlet_spawn
    value = await result
            ^^^^^^^^^^^^
  File "C:\Users\Raphael\AppData\Local\Programs\Python\Python311\Lib\site-packages\sqlalchemy\dialects\postgresql\asyncpg.py", line 558, in _prepare_and_execute
    self._handle_exception(error)
  File "C:\Users\Raphael\AppData\Local\Programs\Python\Python311\Lib\site-packages\sqlalchemy\dialects\postgresql\asyncpg.py", line 508, in _handle_exception
    self._adapt_connection._handle_exception(error)
  File "C:\Users\Raphael\AppData\Local\Programs\Python\Python311\Lib\site-packages\sqlalchemy\dialects\postgresql\asyncpg.py", line 792, in _handle_exception
    raise translated_error from error
sqlalchemy.exc.IntegrityError: (sqlalchemy.dialects.postgresql.asyncpg.IntegrityError) <class 'asyncpg.exceptions.NotNullViolationError'>: o valor nulo na coluna "store_id" da relação "customers" viola a restrição de não-nulo
DETAIL:  Registro que falhou contém (4, Raphael, 16996440178, raphaeldestefanobraga@gmail.com, null, null, null, 0, 0, 2025-10-17 10:23:02.196927, 2025-10-17 10:23:02.196927).
[SQL: INSERT INTO customers (full_name, phone_number, email, document_number, store_id, last_seen, total_spent, loyalty_points, created_at, updated_at) VALUES ($1::VARCHAR, $2::VARCHAR, $3::VARCHAR, $4::VARCHAR, $5::INTEGER, $6::TIMESTAMP WITHOUT TIME ZONE, $7::FLOAT, $8::INTEGER, now(), now()) RETURNING customers.id, customers.created_at, customers.updated_at]
[parameters: ('Raphael', '16996440178', 'raphaeldestefanobraga@gmail.com', None, None, None, 0.0, 0)]
(Background on this error at: https://sqlalche.me/e/20/gkpj)

2025-10-17 10:23:03.242 | ERROR    | app.core.exception_handler:global_exception_handler:12 - Erro inesperado na requisição: POST http://localhost:8000/api/v1/customers/
2025-10-17 10:23:03.242 | ERROR    | app.core.exception_handler:global_exception_handler:13 - Exceção: (sqlalchemy.dialects.postgresql.asyncpg.IntegrityError) <class 'asyncpg.exceptions.NotNullViolationError'>: o valor nulo na coluna "store_id" da relação "customers" viola a restrição de não-nulo
DETAIL:  Registro que falhou contém (5, Raphael, 16996440178, raphaeldestefanobraga@gmail.com, null, null, null, 0, 0, 2025-10-17 10:23:03.243989, 2025-10-17 10:23:03.243989).
[SQL: INSERT INTO customers (full_name, phone_number, email, document_number, store_id, last_seen, total_spent, loyalty_points, created_at, updated_at) VALUES ($1::VARCHAR, $2::VARCHAR, $3::VARCHAR, $4::VARCHAR, $5::INTEGER, $6::TIMESTAMP WITHOUT TIME ZONE, $7::FLOAT, $8::INTEGER, now(), now()) RETURNING customers.id, customers.created_at, customers.updated_at]
[parameters: ('Raphael', '16996440178', 'raphaeldestefanobraga@gmail.com', None, None, None, 0.0, 0)]
(Background on this error at: https://sqlalche.me/e/20/gkpj)
2025-10-17 10:23:03.247 | ERROR    | app.core.exception_handler:global_exception_handler:14 - Traceback: Traceback (most recent call last):
  File "C:\Users\Raphael\AppData\Local\Programs\Python\Python311\Lib\site-packages\sqlalchemy\dialects\postgresql\asyncpg.py", line 545, in _prepare_and_execute
    self._rows = deque(await prepared_stmt.fetch(*parameters))
                       ^^^^^^^^^^^^^^^^^^^^^^^^^^^^^^^^^^^^^^
  File "C:\Users\Raphael\AppData\Local\Programs\Python\Python311\Lib\site-packages\asyncpg\prepared_stmt.py", line 176, in fetch
    data = await self.__bind_execute(args, 0, timeout)
           ^^^^^^^^^^^^^^^^^^^^^^^^^^^^^^^^^^^^^^^^^^^
  File "C:\Users\Raphael\AppData\Local\Programs\Python\Python311\Lib\site-packages\asyncpg\prepared_stmt.py", line 267, in __bind_execute
    data, status, _ = await self.__do_execute(
                      ^^^^^^^^^^^^^^^^^^^^^^^^
  File "C:\Users\Raphael\AppData\Local\Programs\Python\Python311\Lib\site-packages\asyncpg\prepared_stmt.py", line 256, in __do_execute
    return await executor(protocol)
           ^^^^^^^^^^^^^^^^^^^^^^^^
  File "asyncpg\\protocol\\protocol.pyx", line 206, in bind_execute
asyncpg.exceptions.NotNullViolationError: o valor nulo na coluna "store_id" da relação "customers" viola a restrição de não-nulo
DETAIL:  Registro que falhou contém (5, Raphael, 16996440178, raphaeldestefanobraga@gmail.com, null, null, null, 0, 0, 2025-10-17 10:23:03.243989, 2025-10-17 10:23:03.243989).

The above exception was the direct cause of the following exception:

Traceback (most recent call last):
  File "C:\Users\Raphael\AppData\Local\Programs\Python\Python311\Lib\site-packages\sqlalchemy\engine\base.py", line 1967, in _exec_single_context
    self.dialect.do_execute(
  File "C:\Users\Raphael\AppData\Local\Programs\Python\Python311\Lib\site-packages\sqlalchemy\engine\default.py", line 951, in do_execute
    cursor.execute(statement, parameters)
  File "C:\Users\Raphael\AppData\Local\Programs\Python\Python311\Lib\site-packages\sqlalchemy\dialects\postgresql\asyncpg.py", line 580, in execute
    self._adapt_connection.await_(
  File "C:\Users\Raphael\AppData\Local\Programs\Python\Python311\Lib\site-packages\sqlalchemy\util\_concurrency_py3k.py", line 132, in await_only
    return current.parent.switch(awaitable)  # type: ignore[no-any-return,attr-defined] # noqa: E501
           ^^^^^^^^^^^^^^^^^^^^^^^^^^^^^^^^
  File "C:\Users\Raphael\AppData\Local\Programs\Python\Python311\Lib\site-packages\sqlalchemy\util\_concurrency_py3k.py", line 196, in greenlet_spawn
    value = await result
            ^^^^^^^^^^^^
  File "C:\Users\Raphael\AppData\Local\Programs\Python\Python311\Lib\site-packages\sqlalchemy\dialects\postgresql\asyncpg.py", line 558, in _prepare_and_execute
    self._handle_exception(error)
  File "C:\Users\Raphael\AppData\Local\Programs\Python\Python311\Lib\site-packages\sqlalchemy\dialects\postgresql\asyncpg.py", line 508, in _handle_exception
    self._adapt_connection._handle_exception(error)
  File "C:\Users\Raphael\AppData\Local\Programs\Python\Python311\Lib\site-packages\sqlalchemy\dialects\postgresql\asyncpg.py", line 792, in _handle_exception
    raise translated_error from error
sqlalchemy.dialects.postgresql.asyncpg.AsyncAdapt_asyncpg_dbapi.IntegrityError: <class 'asyncpg.exceptions.NotNullViolationError'>: o valor nulo na coluna "store_id" da relação "customers" viola a restrição de não-nulo
DETAIL:  Registro que falhou contém (5, Raphael, 16996440178, raphaeldestefanobraga@gmail.com, null, null, null, 0, 0, 2025-10-17 10:23:03.243989, 2025-10-17 10:23:03.243989).

The above exception was the direct cause of the following exception:

Traceback (most recent call last):
  File "C:\Users\Raphael\AppData\Local\Programs\Python\Python311\Lib\site-packages\starlette\middleware\errors.py", line 164, in __call__
    await self.app(scope, receive, _send)
  File "C:\Users\Raphael\AppData\Local\Programs\Python\Python311\Lib\site-packages\starlette\middleware\cors.py", line 93, in __call__
    await self.simple_response(scope, receive, send, request_headers=headers)
  File "C:\Users\Raphael\AppData\Local\Programs\Python\Python311\Lib\site-packages\starlette\middleware\cors.py", line 144, in simple_response
    await self.app(scope, receive, send)
  File "C:\Users\Raphael\AppData\Local\Programs\Python\Python311\Lib\site-packages\starlette\middleware\base.py", line 182, in __call__
    with recv_stream, send_stream, collapse_excgroups():
  File "C:\Users\Raphael\AppData\Local\Programs\Python\Python311\Lib\contextlib.py", line 158, in __exit__
    self.gen.throw(typ, value, traceback)
  File "C:\Users\Raphael\AppData\Local\Programs\Python\Python311\Lib\site-packages\starlette\_utils.py", line 85, in collapse_excgroups
    raise exc
  File "C:\Users\Raphael\AppData\Local\Programs\Python\Python311\Lib\site-packages\starlette\middleware\base.py", line 184, in __call__
    response = await self.dispatch_func(request, call_next)
               ^^^^^^^^^^^^^^^^^^^^^^^^^^^^^^^^^^^^^^^^^^^^
  File "C:\Users\Raphael\Downloads\VRSales\api\main.py", line 41, in log_requests
    response = await call_next(request)
               ^^^^^^^^^^^^^^^^^^^^^^^^
  File "C:\Users\Raphael\AppData\Local\Programs\Python\Python311\Lib\site-packages\starlette\middleware\base.py", line 159, in call_next
    raise app_exc
  File "C:\Users\Raphael\AppData\Local\Programs\Python\Python311\Lib\site-packages\starlette\middleware\base.py", line 144, in coro
    await self.app(scope, receive_or_disconnect, send_no_error)
  File "C:\Users\Raphael\AppData\Local\Programs\Python\Python311\Lib\site-packages\starlette\middleware\exceptions.py", line 63, in __call__
    await wrap_app_handling_exceptions(self.app, conn)(scope, receive, send)
  File "C:\Users\Raphael\AppData\Local\Programs\Python\Python311\Lib\site-packages\starlette\_exception_handler.py", line 53, in wrapped_app
    raise exc
  File "C:\Users\Raphael\AppData\Local\Programs\Python\Python311\Lib\site-packages\starlette\_exception_handler.py", line 42, in wrapped_app
    await app(scope, receive, sender)
  File "C:\Users\Raphael\AppData\Local\Programs\Python\Python311\Lib\site-packages\fastapi\middleware\asyncexitstack.py", line 18, in __call__
    await self.app(scope, receive, send)
  File "C:\Users\Raphael\AppData\Local\Programs\Python\Python311\Lib\site-packages\starlette\routing.py", line 716, in __call__
    await self.middleware_stack(scope, receive, send)
  File "C:\Users\Raphael\AppData\Local\Programs\Python\Python311\Lib\site-packages\starlette\routing.py", line 736, in app
    await route.handle(scope, receive, send)
  File "C:\Users\Raphael\AppData\Local\Programs\Python\Python311\Lib\site-packages\starlette\routing.py", line 290, in handle
    await self.app(scope, receive, send)
  File "C:\Users\Raphael\AppData\Local\Programs\Python\Python311\Lib\site-packages\fastapi\routing.py", line 123, in app
    await wrap_app_handling_exceptions(app, request)(scope, receive, send)
  File "C:\Users\Raphael\AppData\Local\Programs\Python\Python311\Lib\site-packages\starlette\_exception_handler.py", line 53, in wrapped_app
    raise exc
  File "C:\Users\Raphael\AppData\Local\Programs\Python\Python311\Lib\site-packages\starlette\_exception_handler.py", line 42, in wrapped_app
    await app(scope, receive, sender)
  File "C:\Users\Raphael\AppData\Local\Programs\Python\Python311\Lib\site-packages\fastapi\routing.py", line 109, in app
    response = await f(request)
               ^^^^^^^^^^^^^^^^
  File "C:\Users\Raphael\AppData\Local\Programs\Python\Python311\Lib\site-packages\fastapi\routing.py", line 387, in app
    raw_response = await run_endpoint_function(
                   ^^^^^^^^^^^^^^^^^^^^^^^^^^^^
  File "C:\Users\Raphael\AppData\Local\Programs\Python\Python311\Lib\site-packages\fastapi\routing.py", line 288, in run_endpoint_function
    return await dependant.call(**values)
           ^^^^^^^^^^^^^^^^^^^^^^^^^^^^^^
  File "C:\Users\Raphael\Downloads\VRSales\api\app\api\endpoints\customers.py", line 28, in create_customer
    return await crud.customer.create(db=db, obj_in=customer_in, current_user=current_user)
           ^^^^^^^^^^^^^^^^^^^^^^^^^^^^^^^^^^^^^^^^^^^^^^^^^^^^^^^^^^^^^^^^^^^^^^^^^^^^^^^^
  File "C:\Users\Raphael\Downloads\VRSales\api\app\crud\base.py", line 56, in create
    await db.commit()
  File "C:\Users\Raphael\AppData\Local\Programs\Python\Python311\Lib\site-packages\sqlalchemy\ext\asyncio\session.py", line 1014, in commit
    await greenlet_spawn(self.sync_session.commit)
  File "C:\Users\Raphael\AppData\Local\Programs\Python\Python311\Lib\site-packages\sqlalchemy\util\_concurrency_py3k.py", line 203, in greenlet_spawn
    result = context.switch(value)
             ^^^^^^^^^^^^^^^^^^^^^
  File "C:\Users\Raphael\AppData\Local\Programs\Python\Python311\Lib\site-packages\sqlalchemy\orm\session.py", line 2032, in commit
    trans.commit(_to_root=True)
  File "<string>", line 2, in commit
  File "C:\Users\Raphael\AppData\Local\Programs\Python\Python311\Lib\site-packages\sqlalchemy\orm\state_changes.py", line 137, in _go
    ret_value = fn(self, *arg, **kw)
                ^^^^^^^^^^^^^^^^^^^^
  File "C:\Users\Raphael\AppData\Local\Programs\Python\Python311\Lib\site-packages\sqlalchemy\orm\session.py", line 1313, in commit
    self._prepare_impl()
  File "<string>", line 2, in _prepare_impl
  File "C:\Users\Raphael\AppData\Local\Programs\Python\Python311\Lib\site-packages\sqlalchemy\orm\state_changes.py", line 137, in _go
    ret_value = fn(self, *arg, **kw)
                ^^^^^^^^^^^^^^^^^^^^
  File "C:\Users\Raphael\AppData\Local\Programs\Python\Python311\Lib\site-packages\sqlalchemy\orm\session.py", line 1288, in _prepare_impl
    self.session.flush()
  File "C:\Users\Raphael\AppData\Local\Programs\Python\Python311\Lib\site-packages\sqlalchemy\orm\session.py", line 4345, in flush
    self._flush(objects)
  File "C:\Users\Raphael\AppData\Local\Programs\Python\Python311\Lib\site-packages\sqlalchemy\orm\session.py", line 4480, in _flush
    with util.safe_reraise():
  File "C:\Users\Raphael\AppData\Local\Programs\Python\Python311\Lib\site-packages\sqlalchemy\util\langhelpers.py", line 224, in __exit__
    raise exc_value.with_traceback(exc_tb)
  File "C:\Users\Raphael\AppData\Local\Programs\Python\Python311\Lib\site-packages\sqlalchemy\orm\session.py", line 4441, in _flush
    flush_context.execute()
  File "C:\Users\Raphael\AppData\Local\Programs\Python\Python311\Lib\site-packages\sqlalchemy\orm\unitofwork.py", line 466, in execute
    rec.execute(self)
  File "C:\Users\Raphael\AppData\Local\Programs\Python\Python311\Lib\site-packages\sqlalchemy\orm\unitofwork.py", line 642, in execute
    util.preloaded.orm_persistence.save_obj(
  File "C:\Users\Raphael\AppData\Local\Programs\Python\Python311\Lib\site-packages\sqlalchemy\orm\persistence.py", line 93, in save_obj
    _emit_insert_statements(
  File "C:\Users\Raphael\AppData\Local\Programs\Python\Python311\Lib\site-packages\sqlalchemy\orm\persistence.py", line 1233, in _emit_insert_statements
    result = connection.execute(
             ^^^^^^^^^^^^^^^^^^^
  File "C:\Users\Raphael\AppData\Local\Programs\Python\Python311\Lib\site-packages\sqlalchemy\engine\base.py", line 1419, in execute
    return meth(
           ^^^^^
  File "C:\Users\Raphael\AppData\Local\Programs\Python\Python311\Lib\site-packages\sqlalchemy\sql\elements.py", line 526, in _execute_on_connection
    return connection._execute_clauseelement(
           ^^^^^^^^^^^^^^^^^^^^^^^^^^^^^^^^^^
  File "C:\Users\Raphael\AppData\Local\Programs\Python\Python311\Lib\site-packages\sqlalchemy\engine\base.py", line 1641, in _execute_clauseelement
    ret = self._execute_context(
          ^^^^^^^^^^^^^^^^^^^^^^
  File "C:\Users\Raphael\AppData\Local\Programs\Python\Python311\Lib\site-packages\sqlalchemy\engine\base.py", line 1846, in _execute_context
    return self._exec_single_context(
           ^^^^^^^^^^^^^^^^^^^^^^^^^^
  File "C:\Users\Raphael\AppData\Local\Programs\Python\Python311\Lib\site-packages\sqlalchemy\engine\base.py", line 1986, in _exec_single_context
    self._handle_dbapi_exception(
  File "C:\Users\Raphael\AppData\Local\Programs\Python\Python311\Lib\site-packages\sqlalchemy\engine\base.py", line 2355, in _handle_dbapi_exception
    raise sqlalchemy_exception.with_traceback(exc_info[2]) from e
  File "C:\Users\Raphael\AppData\Local\Programs\Python\Python311\Lib\site-packages\sqlalchemy\engine\base.py", line 1967, in _exec_single_context
    self.dialect.do_execute(
  File "C:\Users\Raphael\AppData\Local\Programs\Python\Python311\Lib\site-packages\sqlalchemy\engine\default.py", line 951, in do_execute
    cursor.execute(statement, parameters)
  File "C:\Users\Raphael\AppData\Local\Programs\Python\Python311\Lib\site-packages\sqlalchemy\dialects\postgresql\asyncpg.py", line 580, in execute
    self._adapt_connection.await_(
  File "C:\Users\Raphael\AppData\Local\Programs\Python\Python311\Lib\site-packages\sqlalchemy\util\_concurrency_py3k.py", line 132, in await_only
    return current.parent.switch(awaitable)  # type: ignore[no-any-return,attr-defined] # noqa: E501
           ^^^^^^^^^^^^^^^^^^^^^^^^^^^^^^^^
  File "C:\Users\Raphael\AppData\Local\Programs\Python\Python311\Lib\site-packages\sqlalchemy\util\_concurrency_py3k.py", line 196, in greenlet_spawn
    value = await result
            ^^^^^^^^^^^^
  File "C:\Users\Raphael\AppData\Local\Programs\Python\Python311\Lib\site-packages\sqlalchemy\dialects\postgresql\asyncpg.py", line 558, in _prepare_and_execute
    self._handle_exception(error)
  File "C:\Users\Raphael\AppData\Local\Programs\Python\Python311\Lib\site-packages\sqlalchemy\dialects\postgresql\asyncpg.py", line 508, in _handle_exception
    self._adapt_connection._handle_exception(error)
  File "C:\Users\Raphael\AppData\Local\Programs\Python\Python311\Lib\site-packages\sqlalchemy\dialects\postgresql\asyncpg.py", line 792, in _handle_exception
    raise translated_error from error
sqlalchemy.exc.IntegrityError: (sqlalchemy.dialects.postgresql.asyncpg.IntegrityError) <class 'asyncpg.exceptions.NotNullViolationError'>: o valor nulo na coluna "store_id" da relação "customers" viola a restrição de não-nulo
DETAIL:  Registro que falhou contém (5, Raphael, 16996440178, raphaeldestefanobraga@gmail.com, null, null, null, 0, 0, 2025-10-17 10:23:03.243989, 2025-10-17 10:23:03.243989).
[SQL: INSERT INTO customers (full_name, phone_number, email, document_number, store_id, last_seen, total_spent, loyalty_points, created_at, updated_at) VALUES ($1::VARCHAR, $2::VARCHAR, $3::VARCHAR, $4::VARCHAR, $5::INTEGER, $6::TIMESTAMP WITHOUT TIME ZONE, $7::FLOAT, $8::INTEGER, now(), now()) RETURNING customers.id, customers.created_at, customers.updated_at]
[parameters: ('Raphael', '16996440178', 'raphaeldestefanobraga@gmail.com', None, None, None, 0.0, 0)]
(Background on this error at: https://sqlalche.me/e/20/gkpj)

2025-10-17 10:24:14.143 | INFO     | main:log_requests:47 - Request: GET /docs | Status: 200 | Duration: 1.04ms
2025-10-17 10:24:14.792 | INFO     | main:log_requests:47 - Request: GET /openapi.json | Status: 200 | Duration: 101.69ms
2025-10-17 10:25:17.827 | INFO     | main:log_requests:47 - Request: POST /api/v1/users/ | Status: 422 | Duration: 0.00ms
2025-10-17 10:25:18.692 | INFO     | main:log_requests:47 - Request: POST /api/v1/users/ | Status: 422 | Duration: 0.00ms
2025-10-17 10:25:20.101 | INFO     | main:log_requests:47 - Request: POST /api/v1/users/ | Status: 422 | Duration: 2.01ms
2025-10-17 10:25:45.779 | INFO     | main:log_requests:47 - Request: POST /api/v1/users/ | Status: 422 | Duration: 1.00ms
